<?xml version="1.0" encoding="utf-8"?><testsuites name="pytest tests"><testsuite name="pytest" errors="0" failures="2" skipped="0" tests="4" time="0.084" timestamp="2025-08-29T10:20:45.148851-05:00" hostname="FAMILIAHERRERA"><testcase classname="tests.test_multiplicacion" name="test_multiplicar" time="0.000" /><testcase classname="tests.test_multiplicacion" name="test_multiplicar_fallo" time="0.001"><failure message="assert 6 == 5&#10; +  where 6 = multiplicar(2, 3)">def test_multiplicar_fallo():
&gt;       assert multiplicar(2, 3) == 5  # Este test est치 dise침ado para fallar
E       assert 6 == 5
E        +  where 6 = multiplicar(2, 3)

tests\test_multiplicacion.py:14: AssertionError</failure></testcase><testcase classname="tests.test_suma" name="test_suma" time="0.000" /><testcase classname="tests.test_suma" name="test_suma_fail" time="0.000"><failure message="assert 3 == 4&#10; +  where 3 = suma(1, 2)">def test_suma_fail():
&gt;       assert suma(1, 2) == 4  # Este test est치 dise침ado para fallar
E       assert 3 == 4
E        +  where 3 = suma(1, 2)

tests\test_suma.py:14: AssertionError</failure></testcase></testsuite></testsuites>